Workbook
Name Slicer_abonoment_type: #N/A
Name Slicer_Age: #N/A
Name Slicer_gender: #N/A
Name Slicer_name_personal_trainer: #N/A

Sheet Dashboard

Sheet gym_membership
A1: id | B1: gender | C1: birthday | D1: Age | E1: Age2 | F1: abonoment_type | G1: visit_per_week | H1: days_per_week | I1: Day 1 | J1: Day 2 | K1: Day 3 | L1: Day 4 | M1: Day 5 | N1: attend_group_lesson | O1: fav_group_lesson | P1: fav_group_lesson1 | Q1: fav_group_lesson2 | R1: fav_group_lesson3 | S1: avg_time_check_in | T1: avg_time_check_out | U1: avg_time_in_gym | V1: drink_abo | W1: fav_drink | X1: fav_drink1 | Y1: fav_drink2 | Z1: personal_training | AA1: name_personal_trainer | AB1: uses_sauna
A2: 1 | B2: Female | C2: 35538 | D2: =DATEDIF(gym_membership[[#This Row],[birthday]],TODAY(),"y") -> 29 | E2: 27 | F2: Premium | G2: 4 | H2: Mon, Sat, Tue, Wed | I2: Mon | J2: Sat | K2: Tue | L2: Wed | N2: TRUE | O2: Kickboxen, BodyPump, Zumba | P2: Kickboxen | Q2: BodyPump | R2: Zumba | S2: 0.81319444 | T2: 0.89375 | U2: 116 | V2: FALSE | Z2: FALSE | AA2: No trainer | AB2: TRUE
A3: 2 | B3: Female | C3: 28386 | D3: =DATEDIF(gym_membership[[#This Row],[birthday]],TODAY(),"y") -> 48 | E3: 47 | F3: Standard | G3: 3 | H3: Mon, Sat, Wed | I3: Mon | J3: Sat | K3: Wed | N3: FALSE | S3: 0.81319444 | T3: 0.84652778 | U3: 48 | V3: FALSE | Z3: TRUE | AA3: Chantal | AB3: FALSE
A4: 3 | B4: Male | C4: 30405 | D4: =DATEDIF(gym_membership[[#This Row],[birthday]],TODAY(),"y") -> 43 | E4: 41 | F4: Premium | G4: 1 | H4: Sat | I4: Sat | N4: TRUE | O4: XCore | P4: XCore | S4: 0.35347222 | T4: 0.43888889 | U4: 123 | V4: TRUE | W4: berry_boost, lemon | X4: berry_boost | Y4: lemon | Z4: TRUE | AA4: Mike | AB4: FALSE
A5: 4 | B5: Male | C5: 29323 | D5: =DATEDIF(gym_membership[[#This Row],[birthday]],TODAY(),"y") -> 46 | E5: 44 | F5: Premium | G5: 3 | H5: Sat, Tue, Wed | I5: Sat | J5: Tue | K5: Wed | N5: FALSE | S5: 0.4125 | T5: 0.48125 | U5: 99 | V5: TRUE | W5: passion_fruit | X5: passion_fruit | Z5: TRUE | AA5: Mike | AB5: TRUE
A6: 5 | B6: Male | C6: 29474 | D6: =DATEDIF(gym_membership[[#This Row],[birthday]],TODAY(),"y") -> 45 | E6: 44 | F6: Standard | G6: 2 | H6: Thu, Wed | I6: Thu | J6: Wed | N6: TRUE | O6: Running, Yoga, Zumba | P6: Running | Q6: Yoga | R6: Zumba | S6: 0.35347222 | T6: 0.38819444 | U6: 50 | V6: FALSE | Z6: TRUE | AA6: Mike | AB6: FALSE
A7: 6 | B7: Female | C7: 39993 | D7: =DATEDIF(gym_membership[[#This Row],[birthday]],TODAY(),"y") -> 17 | E7: 15 | F7: Standard | G7: 1 | H7: Mon | I7: Mon | N7: FALSE | S7: 0.72152778 | T7: 0.84652778 | U7: 180 | V7: FALSE | Z7: FALSE | AA7: No trainer | AB7: TRUE
A8: 7 | B8: Male | C8: 34553 | D8: =DATEDIF(gym_membership[[#This Row],[birthday]],TODAY(),"y") -> 32 | E8: 30 | F8: Premium | G8: 3 | H8: Sat, Thu, Wed | I8: Sat | J8: Thu | K8: Wed | N8: TRUE | O8: LesMiles, BodyPump | P8: LesMiles | Q8: BodyPump | S8: 0.82361111 | T8: 0.86666667 | U8: 62 | V8: FALSE | Z8: FALSE | AA8: No trainer | AB8: FALSE
A9: 8 | B9: Male | C9: 37938 | D9: =DATEDIF(gym_membership[[#This Row],[birthday]],TODAY(),"y") -> 22 | E9: 20 | F9: Standard | G9: 2 | H9: Mon, Wed | I9: Mon | J9: Wed | N9: TRUE | O9: Yoga, XCore | P9: Yoga | Q9: XCore | S9: 0.73958333 | T9: 0.80555556 | U9: 95 | V9: TRUE | W9: coconut_pineapple | X9: coconut_pineapple | Z9: FALSE | AA9: No trainer | AB9: TRUE
A10: 9 | B10: Male | C10: 28699 | D10: =DATEDIF(gym_membership[[#This Row],[birthday]],TODAY(),"y") -> 48 | E10: 46 | F10: Premium | G10: 3 | H10: Sat, Sun, Thu | I10: Sat | J10: Sun | K10: Thu | N10: TRUE | O10: BodyPump | P10: BodyPump | S10: 0.40625 | T10: 0.47013889 | U10: 92 | V10: TRUE | W10: orange, lemon | X10: orange | Y10: lemon | Z10: TRUE | AA10: Mike | AB10: FALSE
A11: 10 | B11: Female | C11: 36652 | D11: =DATEDIF(gym_membership[[#This Row],[birthday]],TODAY(),"y") -> 26 | E11: 24 | F11: Premium | G11: 1 | H11: Mon | I11: Mon | N11: FALSE | S11: 0.54513889 | T11: 0.64513889 | U11: 144 | V11: FALSE | Z11: TRUE | AA11: Jeffrey | AB11: TRUE
A12: 11 | B12: Male | C12: 30508 | D12: =DATEDIF(gym_membership[[#This Row],[birthday]],TODAY(),"y") -> 43 | E12: 41 | F12: Standard | G12: 1 | H12: Fri | I12: Fri | N12: FALSE | S12: 0.57638889 | T12: 0.60138889 | U12: 36 | V12: FALSE | Z12: TRUE | AA12: Hanna | AB12: FALSE
A13: 12 | B13: Male | C13: 35692 | D13: =DATEDIF(gym_membership[[#This Row],[birthday]],TODAY(),"y") -> 28 | E13: 27 | F13: Premium | G13: 3 | H13: Fri, Thu, Wed | I13: Fri | J13: Thu | K13: Wed | N13: TRUE | O13: Pilates, Zumba, XCore | P13: Pilates | Q13: Zumba | R13: XCore | S13: 0.425 | T13: 0.44791667 | U13: 33 | V13: TRUE | W13: passion_fruit | X13: passion_fruit | Z13: TRUE | AA13: Mike | AB13: TRUE
A14: 13 | B14: Female | C14: 34446 | D14: =DATEDIF(gym_membership[[#This Row],[birthday]],TODAY(),"y") -> 32 | E14: 30 | F14: Standard | G14: 2 | H14: Sun, Wed | I14: Sun | J14: Wed | N14: TRUE | O14: XCore, HIT, Running | P14: XCore | Q14: HIT | R14: Running | S14: 0.71111111 | T14: 0.82083333 | U14: 158 | V14: TRUE | W14: passion_fruit | X14: passion_fruit | Z14: FALSE | AA14: No trainer | AB14: TRUE
A15: 14 | B15: Female | C15: 32588 | D15: =DATEDIF(gym_membership[[#This Row],[birthday]],TODAY(),"y") -> 37 | E15: 35 | F15: Premium | G15: 3 | H15: Mon, Tue, Wed | I15: Mon | J15: Tue | K15: Wed | N15: FALSE | S15: 0.82638889 | T15: 0.86875 | U15: 61 | V15: TRUE | W15: black_currant | X15: black_currant | Z15: FALSE | AA15: No trainer | AB15: FALSE
A16: 15 | B16: Female | C16: 32782 | D16: =DATEDIF(gym_membership[[#This Row],[birthday]],TODAY(),"y") -> 36 | E16: 35 | F16: Premium | G16: 1 | H16: Sat | I16: Sat | N16: FALSE | S16: 0.84166667 | T16: 0.94236111 | U16: 145 | V16: TRUE | W16: orange, black_currant | X16: orange | Y16: black_currant | Z16: TRUE | AA16: Mike | AB16: FALSE
A17: 16 | B17: Female | C17: 32131 | D17: =DATEDIF(gym_membership[[#This Row],[birthday]],TODAY(),"y") -> 38 | E17: 36 | F17: Standard | G17: 4 | H17: Mon, Thu, Tue, Wed | I17: Mon | J17: Thu | K17: Tue | L17: Wed | N17: TRUE | O17: Spinning, Zumba, XCore | P17: Spinning | Q17: Zumba | R17: XCore | S17: 0.72777778 | T17: 0.77013889 | U17: 61 | V17: FALSE | Z17: FALSE | AA17: No trainer | AB17: FALSE
A18: 17 | B18: Male | C18: 31763 | D18: =DATEDIF(gym_membership[[#This Row],[birthday]],TODAY(),"y") -> 39 | E18: 37 | F18: Premium | G18: 3 | H18: Fri, Sat, Sun | I18: Fri | J18: Sat | K18: Sun | N18: FALSE | S18: 0.39236111 | T18: 0.50416667 | U18: 161 | V18: FALSE | Z18: TRUE | AA18: Jeffrey | AB18: TRUE
A19: 18 | B19: Female | C19: 40663 | D19: =DATEDIF(gym_membership[[#This Row],[birthday]],TODAY(),"y") -> 15 | E19: 13 | F19: Standard | G19: 3 | H19: Sat, Thu, Tue | I19: Sat | J19: Thu | K19: Tue | N19: FALSE | S19: 0.70416667 | T19: 0.78680556 | U19: 119 | V19: FALSE | Z19: TRUE | AA19: Mike | AB19: TRUE
A20: 19 | B20: Female | C20: 31561 | D20: =DATEDIF(gym_membership[[#This Row],[birthday]],TODAY(),"y") -> 40 | E20: 38 | F20: Standard | G20: 1 | H20: Tue | I20: Tue | N20: TRUE | O20: Pilates | P20: Pilates | S20: 0.41736111 | T20: 0.53333333 | U20: 167 | V20: TRUE | W20: orange | X20: orange | Z20: TRUE | AA20: Hanna | AB20: TRUE
A21: 20 | B21: Male | C21: 33494 | D21: =DATEDIF(gym_membership[[#This Row],[birthday]],TODAY(),"y") -> 34 | E21: 33 | F21: Premium | G21: 2 | H21: Sat, Wed | I21: Sat | J21: Wed | N21: TRUE | O21: BodyPump, Zumba, Pilates | P21: BodyPump | Q21: Zumba | R21: Pilates | S21: 0.57986111 | T21: 0.68333333 | U21: 149 | V21: FALSE | Z21: FALSE | AA21: No trainer | AB21: FALSE
A22: 21 | B22: Female | C22: 35795 | D22: =DATEDIF(gym_membership[[#This Row],[birthday]],TODAY(),"y") -> 28 | E22: 26 | F22: Premium | G22: 2 | H22: Fri, Mon | I22: Fri | J22: Mon | N22: FALSE | S22: 0.34652778 | T22: 0.44791667 | U22: 146 | V22: FALSE | Z22: TRUE | AA22: Hanna | AB22: FALSE
A23: 22 | B23: Male | C23: 35732 | D23: =DATEDIF(gym_membership[[#This Row],[birthday]],TODAY(),"y") -> 28 | E23: 26 | F23: Premium | G23: 3 | H23: Fri, Mon, Sat | I23: Fri | J23: Mon | K23: Sat | N23: TRUE | O23: Yoga, BodyBalance, LesMiles | P23: Yoga | Q23: BodyBalance | R23: LesMiles | S23: 0.62916667 | T23: 0.73611111 | U23: 154 | V23: TRUE | W23: lemon | X23: lemon | Z23: FALSE | AA23: No trainer | AB23: TRUE
A24: 23 | B24: Female | C24: 40473 | D24: =DATEDIF(gym_membership[[#This Row],[birthday]],TODAY(),"y") -> 15 | E24: 13 | F24: Standard | G24: 2 | H24: Mon, Tue | I24: Mon | J24: Tue | N24: TRUE | O24: HIT | P24: HIT | S24: 0.87222222 | T24: 0.98333333 | U24: 160 | V24: TRUE | W24: passion_fruit, orange | X24: passion_fruit | Y24: orange | Z24: TRUE | AA24: Mike | AB24: FALSE
A25: 24 | B25: Male | C25: 40202 | D25: =DATEDIF(gym_membership[[#This Row],[birthday]],TODAY(),"y") -> 16 | E25: 14 | F25: Premium | G25: 3 | H25: Sat, Tue, Wed | I25: Sat | J25: Tue | K25: Wed | N25: FALSE | S25: 0.60694444 | T25: 0.68958333 | U25: 119 | V25: TRUE | W25: lemon, coconut_pineapple | X25: lemon | Y25: coconut_pineapple | Z25: TRUE | AA25: Jeffrey | AB25: TRUE
A26: 25 | B26: Female | C26: 39725 | D26: =DATEDIF(gym_membership[[#This Row],[birthday]],TODAY(),"y") -> 17 | E26: 16 | F26: Premium | G26: 1 | H26: Fri | I26: Fri | N26: FALSE | S26: 0.3625 | T26: 0.44027778 | U26: 112 | V26: FALSE | Z26: FALSE | AA26: No trainer | AB26: FALSE
A27: 26 | B27: Male | C27: 32676 | D27: =DATEDIF(gym_membership[[#This Row],[birthday]],TODAY(),"y") -> 37 | E27: 35 | F27: Standard | G27: 1 | H27: Fri | I27: Fri | N27: TRUE | O27: BodyBalance, Zumba, Yoga | P27: BodyBalance | Q27: Zumba | R27: Yoga | S27: 0.55 | T27: 0.62083333 | U27: 102 | V27: TRUE | W27: coconut_pineapple | X27: coconut_pineapple | Z27: TRUE | AA27: Chantal | AB27: FALSE
A28: 27 | B28: Male | C28: 38442 | D28: =DATEDIF(gym_membership[[#This Row],[birthday]],TODAY(),"y") -> 21 | E28: 19 | F28: Premium | G28: 3 | H28: Fri, Sun, Wed | I28: Fri | J28: Sun | K28: Wed | N28: TRUE | O28: Zumba | P28: Zumba | S28: 0.62569444 | T28: 0.70763889 | U28: 118 | V28: TRUE | W28: berry_boost, passion_fruit | X28: berry_boost | Y28: passion_fruit | Z28: FALSE | AA28: No trainer | AB28: FALSE
A29: 28 | B29: Male | C29: 33704 | D29: =DATEDIF(gym_membership[[#This Row],[birthday]],TODAY(),"y") -> 34 | E29: 32 | F29: Standard | G29: 5 | H29: Fri, Sat, Sun, Tue, Wed | I29: Fri | J29: Sat | K29: Sun | L29: Tue | M29: Wed | N29: TRUE | O29: BodyBalance, Pilates, Running | P29: BodyBalance | Q29: Pilates | R29: Running | S29: 0.82013889 | T29: 0.89930556 | U29: 114 | V29: TRUE | W29: berry_boost | X29: berry_boost | Z29: TRUE | AA29: Chantal | AB29: FALSE
A30: 29 | B30: Female | C30: 35451 | D30: =DATEDIF(gym_membership[[#This Row],[birthday]],TODAY(),"y") -> 29 | E30: 27 | F30: Premium | G30: 1 | H30: Wed | I30: Wed | N30: FALSE | S30: 0.47569444 | T30: 0.53888889 | U30: 91 | V30: TRUE | W30: orange | X30: orange | Z30: FALSE | AA30: No trainer | AB30: TRUE
A31: 30 | B31: Female | C31: 37564 | D31: =DATEDIF(gym_membership[[#This Row],[birthday]],TODAY(),"y") -> 23 | E31: 21 | F31: Premium | G31: 3 | H31: Fri, Mon, Thu | I31: Fri | J31: Mon | K31: Thu | N31: TRUE | O31: Spinning, BodyPump, Zumba | P31: Spinning | Q31: BodyPump | R31: Zumba | S31: 0.84375 | T31: 0.9 | U31: 81 | V31: TRUE | W31: orange, coconut_pineapple | X31: orange | Y31: coconut_pineapple | Z31: FALSE | AA31: No trainer | AB31: TRUE
A32: 31 | B32: Male | C32: 32206 | D32: =DATEDIF(gym_membership[[#This Row],[birthday]],TODAY(),"y") -> 38 | E32: 36 | F32: Premium | G32: 3 | H32: Sun, Thu, Wed | I32: Sun | J32: Thu | K32: Wed | N32: FALSE | S32: 0.41736111 | T32: 0.50763889 | U32: 130 | V32: FALSE | Z32: TRUE | AA32: Jeffrey | AB32: TRUE
A33: 32 | B33: Male | C33: 36587 | D33: =DATEDIF(gym_membership[[#This Row],[birthday]],TODAY(),"y") -> 26 | E33: 24 | F33: Standard | G33: 5 | H33: Fri, Mon, Sat, Sun, Wed | I33: Fri | J33: Mon | K33: Sat | L33: Sun | M33: Wed | N33: FALSE | S33: 0.87013889 | T33: 0.98125 | U33: 160 | V33: TRUE | W33: black_currant, lemon | X33: black_currant | Y33: lemon | Z33: FALSE | AA33: No trainer | AB33: FALSE
A34: 33 | B34: Female | C34: 30008 | D34: =DATEDIF(gym_membership[[#This Row],[birthday]],TODAY(),"y") -> 44 | E34: 42 | F34: Premium | G34: 3 | H34: Sat, Sun, Tue | I34: Sat | J34: Sun | K34: Tue | N34: TRUE | O34: LesMiles, HIT | P34: LesMiles | Q34: HIT | S34: 0.43263889 | T34: 0.50069444 | U34: 98 | V34: FALSE | Z34: TRUE | AA34: Chantal | AB34: TRUE
A35: 34 | B35: Female | C35: 28101 | D35: =DATEDIF(gym_membership[[#This Row],[birthday]],TODAY(),"y") -> 49 | E35: 47 | F35: Premium | G35: 2 | H35: Mon, Sat | I35: Mon | J35: Sat | N35: TRUE | O35: XCore, Running, BodyBalance | P35: XCore | Q35: Running | R35: BodyBalance | S35: 0.6125 | T35: 0.67222222 | U35: 86 | V35: FALSE | Z35: TRUE | AA35: Hanna | AB35: TRUE
A36: 35 | B36: Male | C36: 38052 | D36: =DATEDIF(gym_membership[[#This Row],[birthday]],TODAY(),"y") -> 22 | E36: 20 | F36: Premium | G36: 5 | H36: Mon, Sun, Thu, Tue, Wed | I36: Mon | J36: Sun | K36: Thu | L36: Tue | M36: Wed | N36: FALSE | S36: 0.76041667 | T36: 0.87083333 | U36: 159 | V36: FALSE | Z36: TRUE | AA36: Mike | AB36: TRUE
A37: 36 | B37: Male | C37: 32941 | D37: =DATEDIF(gym_membership[[#This Row],[birthday]],TODAY(),"y") -> 36 | E37: 34 | F37: Standard | G37: 3 | H37: Sat, Sun, Tue | I37: Sat | J37: Sun | K37: Tue | N37: TRUE | O37: XCore | P37: XCore | S37: 0.56875 | T37: 0.68055556 | U37: 161 | V37: TRUE | W37: orange | X37: orange | Z37: FALSE | AA37: No trainer | AB37: TRUE
A38: 37 | B38: Female | C38: 29663 | D38: =DATEDIF(gym_membership[[#This Row],[birthday]],TODAY(),"y") -> 45 | E38: 43 | F38: Standard | G38: 5 | H38: Fri, Sat, Sun, Tue, Wed | I38: Fri | J38: Sat | K38: Sun | L38: Tue | M38: Wed | N38: FALSE | S38: 0.37638889 | T38: 0.43125 | U38: 79 | V38: FALSE | Z38: FALSE | AA38: No trainer | AB38: FALSE
A39: 38 | B39: Female | C39: 30621 | D39: =DATEDIF(gym_membership[[#This Row],[birthday]],TODAY(),"y") -> 42 | E39: 40 | F39: Premium | G39: 2 | H39: Sat, Thu | I39: Sat | J39: Thu | N39: FALSE | S39: 0.36041667 | T39: 0.44236111 | U39: 118 | V39: FALSE | Z39: FALSE | AA39: No trainer | AB39: FALSE
A40: 39 | B40: Male | C40: 29407 | D40: =DATEDIF(gym_membership[[#This Row],[birthday]],TODAY(),"y") -> 46 | E40: 44 | F40: Premium | G40: 1 | H40: Wed | I40: Wed | N40: FALSE | S40: 0.86319444 | T40: 0.95694444 | U40: 135 | V40: TRUE | W40: coconut_pineapple, berry_boost | X40: coconut_pineapple | Y40: berry_boost | Z40: FALSE | AA40: No trainer | AB40: FALSE
...

Sheet Sheet1
A11: Days | B11: Number of visits
A12: Mon | B12: =COUNTIF(gym_membership[[Day 1]:[Day 5]],Sheet1!A12) -> 349
A13: Tue | B13: =COUNTIF(gym_membership[[Day 1]:[Day 5]],Sheet1!A13) -> 391
A14: Wed | B14: =COUNTIF(gym_membership[[Day 1]:[Day 5]],Sheet1!A14) -> 400
A15: Thu | B15: =COUNTIF(gym_membership[[Day 1]:[Day 5]],Sheet1!A15) -> 379
A16: Fri | B16: =COUNTIF(gym_membership[[Day 1]:[Day 5]],Sheet1!A16) -> 376
A17: Sat | B17: =COUNTIF(gym_membership[[Day 1]:[Day 5]],Sheet1!A17) -> 380
A18: Sun | B18: =COUNTIF(gym_membership[[Day 1]:[Day 5]],Sheet1!A18) -> 407
A28: Group lesson | B28: Number of lessons
A29: {=_xlfn.UNIQUE(_xlfn._xlws.FILTER(_xlfn.VSTACK(gym_membership[fav_group_lesson1],gym_membership[fav_group_lesson2],gym_membership[fav_group_lesson3]),_xlfn.VSTACK(gym_membership[fav_group_lesson1],gym_membership[fav_group_lesson2],gym_membership[fav_group_lesson3])<>0))} -> Kickboxen | B29: =COUNTIF(gym_membership[[fav_group_lesson1]:[fav_group_lesson3]],Sheet1!A29) -> 85
A30: XCore | B30: =COUNTIF(gym_membership[[fav_group_lesson1]:[fav_group_lesson3]],Sheet1!A30) -> 90
A31: Running | B31: =COUNTIF(gym_membership[[fav_group_lesson1]:[fav_group_lesson3]],Sheet1!A31) -> 82
A32: LesMiles | B32: =COUNTIF(gym_membership[[fav_group_lesson1]:[fav_group_lesson3]],Sheet1!A32) -> 99
A33: Yoga | B33: =COUNTIF(gym_membership[[fav_group_lesson1]:[fav_group_lesson3]],Sheet1!A33) -> 90
A34: BodyPump | B34: =COUNTIF(gym_membership[[fav_group_lesson1]:[fav_group_lesson3]],Sheet1!A34) -> 112
A35: Pilates | B35: =COUNTIF(gym_membership[[fav_group_lesson1]:[fav_group_lesson3]],Sheet1!A35) -> 95
A36: Spinning | B36: =COUNTIF(gym_membership[[fav_group_lesson1]:[fav_group_lesson3]],Sheet1!A36) -> 85
A37: HIT | B37: =COUNTIF(gym_membership[[fav_group_lesson1]:[fav_group_lesson3]],Sheet1!A37) -> 97
A38: BodyBalance | B38: =COUNTIF(gym_membership[[fav_group_lesson1]:[fav_group_lesson3]],Sheet1!A38) -> 87
A39: Zumba | B39: =COUNTIF(gym_membership[[fav_group_lesson1]:[fav_group_lesson3]],Sheet1!A39) -> 81

Sheet Sheet2
A6: Favourite drinks | B6: No of customers
A7: {=_xlfn.UNIQUE(_xlfn._xlws.FILTER(_xlfn.VSTACK(gym_membership[fav_drink1],gym_membership[fav_drink2]),_xlfn.VSTACK(gym_membership[fav_drink1],gym_membership[fav_drink2])<>0))} -> berry_boost | B7: =COUNTIF(gym_membership[[fav_drink1]:[fav_drink2]],Sheet2!A7) -> 114
A8: passion_fruit | B8: =COUNTIF(gym_membership[[fav_drink1]:[fav_drink2]],Sheet2!A8) -> 119
A9: coconut_pineapple | B9: =COUNTIF(gym_membership[[fav_drink1]:[fav_drink2]],Sheet2!A9) -> 134
A10: orange | B10: =COUNTIF(gym_membership[[fav_drink1]:[fav_drink2]],Sheet2!A10) -> 126
A11: black_currant | B11: =COUNTIF(gym_membership[[fav_drink1]:[fav_drink2]],Sheet2!A11) -> 111
A12: lemon | B12: =COUNTIF(gym_membership[[fav_drink1]:[fav_drink2]],Sheet2!A12) -> 115
A20: Gender | B20: No of customers
A21: Female | B21: 503
A22: Male | B22: 497
A23: Grand Total | B23: 1000
A32: Age | B32: No of customers
A33: 13 | B33: 5
A34: 14 | B34: 16
A35: 15 | B35: 26
A36: 16 | B36: 30
A37: 17 | B37: 21
A38: 18 | B38: 23
A39: 19 | B39: 26
A40: 20 | B40: 31
A41: 21 | B41: 27
A42: 22 | B42: 25
A43: 23 | B43: 25
A44: 24 | B44: 25
... A71: 51 | B71: 26
A72: Grand Total | B72: 1000

Sheet Sheet3
A4: Count of id | B4: Column Labels
A5: Row Labels | B5: 1 | C5: 2 | D5: 3 | E5: 4 | F5: 5 | G5: Grand Total
A6: Female | B6: 98 | C6: 132 | D6: 152 | E6: 56 | F6: 65 | G6: 503
A7: Male | B7: 96 | C7: 142 | D7: 160 | E7: 40 | F7: 59 | G7: 497 | R7: Count of id | S7: Column Labels
A8: Grand Total | B8: 194 | C8: 274 | D8: 312 | E8: 96 | F8: 124 | G8: 1000 | R8: Row Labels | S8: Female | T8: Male | U8: Grand Total
R9: Premium | S9: 242 | T9: 251 | U9: 493
R10: Standard | S10: 261 | T10: 246 | U10: 507
R11: Grand Total | S11: 503 | T11: 497 | U11: 1000
A17: Count of id | B17: Column Labels
A18: Row Labels | B18: FALSE | C18: TRUE | D18: Grand Total
A19: Female | B19: 262 | C19: 241 | D19: 503
A20: Male | B20: 245 | C20: 252 | D20: 497
A21: Grand Total | B21: 507 | C21: 493 | D21: 1000

Sheet Sheet4
A4: Average time in Gym | B4: Number of customers
A5: 161 | B5: 12 | T5: Row Labels | U5: Count of id
A6: 156 | B6: 12 | T6: Chantal | U6: 153
A7: 149 | B7: 11 | T7: Hanna | U7: 114
A8: 141 | B8: 12 | T8: Jeffrey | U8: 111
A9: 138 | B9: 12 | T9: Mike | U9: 140
A10: 135 | B10: 11 | T10: No trainer | U10: 482
A11: 107 | B11: 12 | T11: Grand Total | U11: 1000
A12: 105 | B12: 12
A13: 93 | B13: 13
A14: 67 | B14: 14
A15: 56 | B15: 14
A16: Grand Total | B16: 135
A21: Count of id | B21: Column Labels
A22: Row Labels | B22: FALSE | C22: TRUE | D22: Grand Total
A23: Female | B23: 255 | C23: 248 | D23: 503
A24: Male | B24: 227 | C24: 270 | D24: 497
A25: Grand Total | B25: 482 | C25: 518 | D25: 1000
